# Composing Suspending Functions

## Sequential by default

내부에서 일시 중단 함수를 사용하는 두 함수가 있다고 가정해봅시다.
아래는 각 코드에서 1초 씩 지연하고 정해진 숫자를 반환하는 예시입니다.

```
suspend fun doSomethingUsefulOne(): Int {
    delay(1000L) // pretend we are doing something useful here
    return 13
}

suspend fun doSomethingUsefulTwo(): Int {
    delay(1000L) // pretend we are doing something useful here, too
    return 29
}
```


만약 순차적으로 실행하면 어떻게 될까요?
`doSomethingUsefulOne`를 실행한 후 `doSomethingUsefulTwo`를 수행하고 그 결과에 대한 합을 계산해봅시다.
실제로 첫 번째 함수의 결과를 사용하여 두 번째 함수를 사용하는데 있어 필요한지 여부를 파악하는 것이 중요합니다.

일반적인 코드와 동일하게 코루틴의 코드는 기본적으로 순차 실행됩니다.
아래 예시는 두 함수를 모두 사용하는데 걸리는 총 시간을 측정한 것 입니다.

```
val time = measureTimeMillis {
    val one = doSomethingUsefulOne()
    val two = doSomethingUsefulTwo()
    println("The answer is ${one + two}")
}
println("Completed in $time ms")
```

실행 결과는 다음과 같습니다.

```
The answer is 42
Completed in 2017 ms
```


## Concurrent using async

만약 `doSomethingUsefulOne`와 `doSomethingUsefulTwo`의 사이에 종속성이 없어 동시에 실행 가능해서 수행 속도를 높일 수 있다면 어떨까요?
여기서 `async` 실행이 도움이 될 것입니다.

개념적으로 `async`은 `launch`와 유사하게 작동합니다.
이는 비동기적으로 실행되는 코루틴은 다른 코루틴과 별도로 실행됩니다.
다만 차이점은 `launch`의 경우 `Job`이 반한되고 어떠한 결과 값도 전달되지 않지만, `async`은 나중에 결과를 제공하기 위한 `Deferred`를 반환한다는 것 입니다.
또한,  `Deferred` 값에 `await()`를 사용하여 반환 값을 사용할 수 있으며, `Deferred` 또한 `Job`을 상속받은 객체이기 때문에 필요에 따라서 취소할 수 있습니다.

```
val time = measureTimeMillis {
    val one = async { doSomethingUsefulOne() }
    val two = async { doSomethingUsefulTwo() }
    println("The answer is ${one.await() + two.await()}")
}
println("Completed in $time ms")
```

실행 결과는 다음과 같습니다.

```
The answer is 42
Completed in 1017 ms
```

이는 이전에 비해 두 배 가까이 빨라진 것인데, 이는 두 개의 코루틴이 동시에 실행되었기 때문입니다.
동기성을 사용한 코루틴은 항상 명시적이라는 것을 알아두세요.


## Lazily started async

추가적으로, `async`는 `start` 파라미터를 `CoroutineStart.LAZY`로 설정하여 지연 시작을 할 수 있습니다.
이 때 코루틴은 `await` 또는 `Job`의 시작이 호출 될 때만 시작됩니다.
예를 들면 다음과 같습니다.

```
val time = measureTimeMillis {
    val one = async(start = CoroutineStart.LAZY) { doSomethingUsefulOne() }
    val two = async(start = CoroutineStart.LAZY) { doSomethingUsefulTwo() }
    // some computation
    one.start() // start the first one
    two.start() // start the second one
    println("The answer is ${one.await() + two.await()}")
}
println("Completed in $time ms")
```

실행 결과는 다음과 같습니다.

```
The answer is 42
Completed in 1017 ms
```

여기서 앞의 예와 같이 두 개의 코루틴이 정의되었지만 `start`를 통해 실행을 하기 위한 제어를 프로그래머가 할 수 있습니다.
먼저 `one`을 실행한 후 `two`를 실행하며, 각각의 코루틴이 끝날 때 까지 기다립니다.

만약 우리가 각각의 코루틴에 대해 `println`에서 `start`을 부르지 않고 `await`를 부르는 경우 코루틴이 시작 후 끝날 때 까지 대기하기 때문에, 
결과적으로 코루틴이 순차적으로 실행되며, 이는 우리가 원하는 형태의 실행은 아니라는 것을 알아두어야 합니다.


## Async-style functions

명시적으로  `GlobalScope`내 참조에서 `async` 코루틴 빌더를 사용하면 `doSomethingUsefulOne`와 `doSomethingUsefulTwo`를 실행하는 비동기 함수 사용을 할 수 있습니다.
우리는 이러한 함수들의 이름 뒤에 `...Async`라는 접미사를 하용하여 이 함수들이 비동기적으로 사용된다는 것을 강조할 필요가 있으며,
반환된 값을 사용하기 위해 지연 값을 사용하면 됩니다.

```
// The result type of somethingUsefulOneAsync is Deferred<Int>
fun somethingUsefulOneAsync() = GlobalScope.async {
    doSomethingUsefulOne()
}

// The result type of somethingUsefulTwoAsync is Deferred<Int>
fun somethingUsefulTwoAsync() = GlobalScope.async {
    doSomethingUsefulTwo()
}
```

다만, `...Async` 함수는 일시 중단 되지는 않습니다.
그렇기 때문에 어느 곳에서나 사용할 수 있습니다.

이를 코루틴 외부에서 사용하는 예시는 다음과 같습니다.

```
// note that we don't have `runBlocking` to the right of `main` in this example
fun main() {
    val time = measureTimeMillis {
        // we can initiate async actions outside of a coroutine
        val one = somethingUsefulOneAsync()
        val two = somethingUsefulTwoAsync()
        // but waiting for a result must involve either suspending or blocking.
        // here we use `runBlocking { ... }` to block the main thread while waiting for the result
        runBlocking {
            println("The answer is ${one.await() + two.await()}")
        }
    }
    println("Completed in $time ms")
}
```

이 예시는 다른 프로그래밍 언어에서 널리 사용되는 스타일이므로 설명했습니다. 다만, 이러한 코드 스타일은 생각보다 추천되지 않습니다.

만약 `val one = somethingUsefulOneAsync()`과 `one.await()`의 사이에 무언가 오류가 발생하여 수행 중인 프로그램이 종료되는 경우 어떻게 될까요?
일반적으로는 전역 에러 핸들러가 이를 확인한다면 이를 개발자에게 알려주지만, 그럼에도 프로그램은 다른 작업을 수행할 수 있습니다.
예를 들어 `somethingUsefulOneAsync`라는 백그라운드에서 돌아가는 함수가 있을 때, 이를 실행한 작업이 중단되었음에도 계속 종료되지 않고 수행하기 때문입니다.


## Structured concurrency with async

`Concurrent using async`에 대한 에시를 위해 `doSomethingUsefulOne`과 `doSomethingUsefulTwo`를 동시에 실행하여 반환 값의 합을 구하는 함수를 선언해보겠습니다.
`async` 코루틴 빌더는 `CoroutineScope` 내 정의되므로, 이를 범위에 포함해야 합니다.

```
suspend fun concurrentSum(): Int = coroutineScope {
    val one = async { doSomethingUsefulOne() }
    val two = async { doSomethingUsefulTwo() }
    one.await() + two.await()
}
```

이렇게 실행하는 경우, `concurrentSum` 내 오류로 인해 예외가 발생하면 해당 범위 내의 모든 코루틴이 취소됩니다.

```
val time = measureTimeMillis {
    println("The answer is ${concurrentSum()}")
}
println("Completed in $time ms")
```

코드를 보게 되면 여전히 두 함수를 동시에 실행하는 것을 볼 수 있습니다.

```
The answer is 42
Completed in 1017 ms
```

취소는 항상 코루틴 체계를 통해 다른 코루틴으로 전파됩니다.

```
import kotlinx.coroutines.*

fun main() = runBlocking<Unit> {
    try {
        failedConcurrentSum()
    } catch(e: ArithmeticException) {
        println("Computation failed with ArithmeticException")
    }
}

suspend fun failedConcurrentSum(): Int = coroutineScope {
    val one = async<Int> { 
        try {
            delay(Long.MAX_VALUE) // Emulates very long computation
            42
        } finally {
            println("First child was cancelled")
        }
    }
    val two = async<Int> { 
        println("Second child throws an exception")
        throw ArithmeticException()
    }
    one.await() + two.await()
}
```

이 코드를 실행하면 예외 처리로 인해 모두 취소되는 것을 확인할 수 있습니다.

```
Second child throws an exception
First child was cancelled
Computation failed with ArithmeticException
```
