# Exception Handling

exception handling 과 cancellation 에 대해서 알아봅시다.  
cancel 된 코루틴은 suspension 지점에서 CancellationException 을 던집니다.  

## 1. Exception propagation

코루틴 빌더들은 Exception handling 측면에서 2가지 타입으로 나뉩니다.

1. Exception 을 외부로 전파(propagation) 시킴: __launch__, __actor__
2. Exception 을 노출(exposing) 시킴: __async__, __produce__

이런 코루틴 빌더들은 또 다른 코루틴의 자식을 만들지 않고 root 코루틴들을 만드는데 사용됩니다.

laucnh 나 actor 같은 코루틴 빌더는 예외를 uncaught exception 으로 처리합니다.  
(마치 자바의 Thread.uncaughtExceptionHandler 처럼)  
async 나 produce 같은 코루틴 빌더들은 final exception 을 consume 할 때(await 이나 receive 같은 부분) 처리해줘야 합니다.  

```kotlin
import kotlinx.coroutines.*

fun main() = runBlocking {
    val job = GlobalScope.launch { // root coroutine with launch
        println("Throwing exception from launch")
        throw IndexOutOfBoundsException() // Will be printed to the console by Thread.defaultUncaughtExceptionHandler
    }
    job.join()
    println("Joined failed job")
    val deferred = GlobalScope.async { // root coroutine with async
        println("Throwing exception from async")
        throw ArithmeticException() // Nothing is printed, relying on user to call await
    }
    try {
        deferred.await()
        println("Unreached")
    } catch (e: ArithmeticException) {
        println("Caught ArithmeticException")
    }
}
```
```text
Throwing exception from launch
Exception in thread "DefaultDispatcher-worker-2 @coroutine#2" java.lang.IndexOutOfBoundsException
Joined failed job
Throwing exception from async
Caught ArithmeticException
```


## 2. CoroutineExceptionHandler
uncaught exception 을 콘솔에 출력하는 기본적인 방식을 커스터마이징 할 수도 있습니다.  
이를 방지하기 위해 CoroutineExceptionHandler를 이용하여 coroutine 내부의 기본 catch block으로 사용할 수 있습니다.

Java에서 Thread에 사용하는 Thread.defaultUncaughtExceptionHandler와 비슷다하고 생각하면 됩니다.


```kotlin
val handler = CoroutineExceptionHandler { _, exception -> 
    println("CoroutineExceptionHandler got $exception") 
}
val job = GlobalScope.launch(handler) { // root coroutine, running in GlobalScope
    throw AssertionError()
}
val deferred = GlobalScope.async(handler) { // also root, but async instead of launch
    throw ArithmeticException() // Nothing will be printed, relying on user to call deferred.await()
}
joinAll(job, deferred)
```
```text
CoroutineExceptionHandler got java.lang.AssertionError
```

결과를 보면 launch에서 발생한 exception만 처리되었음을 알수있습니다.

async처럼 await()를 만나야 exception이 발생하는 경우에는 동작하지 않습니다.


## 3. Cancellation and exceptions

coroutine은 취소되면 CancellationException을 발생시키는것처럼 exception과 매우 밀접한 관계를 같습니다.

특이하게도 CancellationException은 어떤 handler도 처리하지 않습니다.
따라서 catch를 하지 않아도 exception을 발생시키지는 않습니다.
대신 catch를 이용하여 debug log를 찍거나 finally를 이용해서 resource를 해체하는등의 작업을 할수 있습니다.

또한 Job.cancel()을 통해 coroutine을 취소시 부모는 취소되지 않습니다.
(따라서 부모가 자식을 취소할때 Job.cancel()을 사용할 수 있습니다.)


```kotlin
fun main() = runBlocking {
    val job = launch {
        val child = launch {
            try {
                delay(Long.MAX_VALUE)
            } finally {
                println("Child is cancelled")
            }
        }
        yield()
        println("Cancelling child")
        child.cancel()
        child.join()
        yield()
        println("Parent is not cancelled")
    }
    job.join()
}
```
```text
Cancelling child
Child is cancelled
Parent is not cancelled
```

Coroutine은 취소를 제외한 다른 exception이 발생하면 부모의 corouitne까지 모두 취소 시킵니다.

이런 동작은 structured concurrency를 유지하기 위함이기 때문에, CoroutineExceptionHandler를 설정하더라도 막을 수 없습니다.

```kotlin
fun main() = runBlocking {
    val handler = CoroutineExceptionHandler { _, exception ->
        println("CoroutineExceptionHandler got $exception")
    }
    val job = GlobalScope.launch(handler) {
        launch { // the first child
            try {
                delay(Long.MAX_VALUE)
            } finally {
                withContext(NonCancellable) {
                    println("Children are cancelled, but exception is not handled until all children terminate")
                    delay(100)
                    println("The first child finished its non cancellable block")
                }
            }
        }
        launch { // the second child
            delay(10)
            println("Second child throws an exception")
            throw ArithmeticException()
        }
    }
    job.join()
}
```
```text
Second child throws an exception
Children are cancelled, but exception is not handled until all children terminate
The first child finished its non cancellable block
CoroutineExceptionHandler got java.lang.ArithmeticException
```

자식 코루틴에서 exception이 발생되면 다른 자식 코루틴이 모두 취소된 이후에 부모에 의해서 exception이 handling 됩니다.

위 예제에서는 GlobalScope에 handler를 설정합니다.
이유는 자식 coroutine에서 exception이 발생하면, 다른 자식까지 취소된 후에 runBlocking까지도 취소되기 때문에 이 안에서 exception handling을 해봐야 수행되지 않습니다.

만약 Global.launch 를 this.launch 로 변경하면 어떻게 될까요?  

```kotlin
fun main() = runBlocking {
    val handler = CoroutineExceptionHandler { _, exception ->
        println("CoroutineExceptionHandler got $exception")
    }
    val job = launch(handler) {
        launch { // the first child
            try {
                delay(Long.MAX_VALUE)
            } finally {
                withContext(NonCancellable) {
                    println("Children are cancelled, but exception is not handled until all children terminate")
                    delay(100)
                    println("The first child finished its non cancellable block")
                }
            }
        }
        launch { // the second child
            delay(10)
            println("Second child throws an exception")
            throw ArithmeticException()
        }
    }
    job.join()
}
```
```text
Second child throws an exception
Children are cancelled, but exception is not handled until all children terminate
The first child finished its non cancellable block
Exception in thread "main" java.lang.ArithmeticException
```
자식 코루틴에서 예외가 발생하고 다른 자식 코루틴이 취소 되고 main 의 runBlocking 까지도 취소됩니다.  

## 4. Exceptions aggregation

자식 coroutine에서 여러개의 exception이 발생할 경우 가장 먼저 발생한 exception이 handler로 전달됩니다.
(나머지 exception은 무시됩니다.)  

```kotlin
import kotlinx.coroutines.*
import java.io.*

fun main() = runBlocking {
    val handler = CoroutineExceptionHandler { _, exception ->
        println("CoroutineExceptionHandler got $exception with suppressed ${exception.suppressed.contentToString()}")
    }
    val job = GlobalScope.launch(handler) {
        launch {
            try {
                delay(Long.MAX_VALUE) // it gets cancelled when another sibling fails with IOException
            } finally {
                throw ArithmeticException() // the second exception
            }
        }
        launch {
            delay(100)
            throw IOException() // the first exception
        }
        delay(Long.MAX_VALUE)
    }
    job.join()  
}
```
```text
CoroutineExceptionHandler got java.io.IOException with suppressed 
[java.lang.ArithmeticException]
```

GlobalScope 의 두번째 자식 코루틴에서 먼저 IOException 이 던져져서  
오랫동안 기다리고 있었던 첫번째 자식 코루틴에서도 finally 구문이 불려지게 됩니다.  
이 경우 먼저 던져진 IOException 이 핸들링 되며 그 이후 던져지는 예외들은 첫번째 예외에 suppressed 되는 형태로 합쳐집니다.  
 
Cancellation exception 은 기본적으로는 throw 되더라도 핸들링 되지 않습니다. 

```kotlin
val handler = CoroutineExceptionHandler { _, exception ->
    println("CoroutineExceptionHandler got $exception")
}
val job = GlobalScope.launch(handler) {
    val inner = launch { // all this stack of coroutines will get cancelled
        launch {
            launch {
                throw IOException() // the original exception
            }
        }
    }
    try {
        inner.join()
    } catch (e: CancellationException) {
        println("Rethrowing CancellationException with original cause")
        throw e // cancellation exception is rethrown, yet the original IOException gets to the handler  
    }
}
job.join()
```
```text
Rethrowing CancellationException with original cause
CoroutineExceptionHandler got java.io.IOException
```


## 5. Supervision

코루틴에서 Exception은 자식, 부모 양방향으로 전부 전달됩니다.

UI component 같은곳에서 하나의 Job을 사용하면 UI 자체를 destroy하거나 화면을 떠나는 경우 모든 자식들을 취소 시킬 수 있습니다.

다만, 자식중 하나가 실패되면 모든 UI component가 취소되는 상황도 같이 일어납니다.


#### 5.1. Supervision job

이렇게 한방향으로만 취소를 전달하기 위한 방법으로 SupervisorJob이 있습니다.

SupervisorJob의 경우 아래 방향으로만 취소를 전파시킵니다

```kotlin
import kotlinx.coroutines.*

fun main() = runBlocking {
    val supervisor = SupervisorJob()
    with(CoroutineScope(coroutineContext + supervisor)) {
        // launch the first child -- its exception is ignored for this example (don't do this in practice!)
        val firstChild = launch(CoroutineExceptionHandler { _, _ ->  }) {
            println("The first child is failing")
            throw AssertionError("The first child is cancelled")
        }
        // launch the second child
        val secondChild = launch {
            firstChild.join()
            // Cancellation of the first child is not propagated to the second child
            println("The first child is cancelled: ${firstChild.isCancelled}, but the second one is still active")
            try {
                delay(Long.MAX_VALUE)
            } finally {
                // But cancellation of the supervisor is propagated
                println("The second child is cancelled because the supervisor was cancelled")
            }
        }
        // wait until the first child fails & completes
        firstChild.join()
        println("Cancelling the supervisor")
        supervisor.cancel()
        secondChild.join()
    }
}
```
```text
The first child is failing
The first child is cancelled: true, but the second one is still active
Cancelling the supervisor
The second child is cancelled because the supervisor was cancelled
```

irstChild에서 exception이 발생했으나, 부모로 전달되지 않으므로 secondChild는 정상적으로 수행 됩니다.
firstChild는 어찌됐건 완료가 됩니다.(exception이 발생하더라도 완료 입니다.)
그 이후 supervisor job을 cancel()하면 자식인 secondChild가 취소됩니다.

만약 context에 supervisor를 "+" 하지 않는다면 아래와 같은 로그가 찍힙니다.
First child is failing
CoroutineScope is cancelled!

fisrtChild를 launch하면서 exception이 발생하므로 second child에는 수행조차 안됩니다.
또한 이 exception이 부모 coroutineScope으로 전달되므로 부모 scope도 취소되었다는 로그가 찍힙니다.



#### 5.2. Supervision scope

위와 같은 역할을 하는 supervisorScope도 존재합니다.
위 이는 coroutineScope와 동일한 동작을 하지만 취소에 대한 전파는 자식으로만 진행됩니다.


```kotlin
import kotlin.coroutines.*
import kotlinx.coroutines.*

fun main() = runBlocking {
    try {
        supervisorScope {
            val child = launch {
                try {
                    println("The child is sleeping")
                    delay(Long.MAX_VALUE)
                } finally {
                    println("The child is cancelled")
                }
            }
            // Give our child a chance to execute and print using yield 
            yield()
            println("Throwing an exception from the scope")
            throw AssertionError()
        }
    } catch(e: AssertionError) {
        println("Caught an assertion error")
    }
}
```
```text
The child is sleeping
Throwing an exception from the scope
The child is cancelled
Caught an assertion error
```

supervisorScope를 사용하면 부모로는 취소를 전달하지 않습니다.

위 예제에서는 supervisorScope 자체에서 exception이 발생했으므로 자식인 Child는 취소됩니다.


#### 5.3. Exceptions in supervised coroutines

따라서 supervisorScope을 사용하는 경우에는 필요에 따라 각각의 자식 coroutine에 exception handler를 달아줘야 합니다.

```kotlin
import kotlin.coroutines.*
import kotlinx.coroutines.*

fun main() = runBlocking {
    val handler = CoroutineExceptionHandler { _, exception -> 
        println("CoroutineExceptionHandler got $exception") 
    }
    supervisorScope {
        val child = launch(handler) {
            println("The child throws an exception")
            throw AssertionError()
        }
        println("The scope is completing")
    }
    println("The scope is completed")
}
```
```text
The scope is completing
The child throws an exception
CoroutineExceptionHandler got java.lang.AssertionError
The scope is completed
```


## 참고자료
[[Kotlin] 코틀린 - 코루틴#5 - exception](https://tourspace.tistory.com/154?category=797357)  
[[Kotlin] 코틀린 - 코루틴#6 - supervision](https://tourspace.tistory.com/155?category=797357)
